<mujoco model="quadruped">
    <compiler angle="radian" autolimits="true" inertiafromgeom="true"/>
  
    <option gravity="0 0 -9.81"/>
  
    <size nstack="3000"/>
  
    <custom>
        <numeric data="10000" name="constraint_stiffness"/>
        <numeric data="10000" name="constraint_limit_stiffness"/>
        <numeric data="10" name="constraint_ang_damping"/>
        <numeric data="50" name="constraint_vel_damping"/>
        <numeric data="0" name="ang_damping"/>
        <numeric data="0" name="spring_mass_scale"/>
        <numeric data="1" name="spring_inertia_scale"/>
        <numeric data="10" name="matrix_inv_iterations"/>
        <numeric data="10" name="solver_maxls"/>
    </custom>

    <default>
        <default class="collision">
            <geom contype="1" conaffinity="1" group="1"/>
        </default>
        <default class="visual">
            <geom contype="0" conaffinity="0" group="2"/>
        </default>
        <default class="motors">
            <general gaintype="fixed" biastype="affine" ctrlrange="-2.0 2.0" gainprm="5" biasprm="0 0 0" gear="1 0 0 0 0 0" forcerange="-33.5 33.5"/>
        </default>
    </default>

    <worldbody>
        <light name="spotlight" mode="targetbodycom" target="base" pos="0 -1 2"/>
        <geom name="floor" size="0 0 0.05" type="plane"/>
        <body name="base" pos="0 0 0.2">
            <freejoint/>
            <geom type="box" size="0.1375 0.095 0.045" pos="0 0 0" quat="1 0 0 0"/>
            <!-- HIP: r=0.45 l=0.5 extended in the y-direction by an extra: 0.015 -->
            <geom class="visual" type="cylinder" size="0.045 0.025" pos="0.1525 0.085 0" quat="1 1 0 0"/>
            <geom class="visual" type="cylinder" size="0.045 0.025" pos="0.1525 -0.085 0" quat="1 1 0 0"/>
            <geom class="visual" type="cylinder" size="0.045 0.025" pos="-0.1525 -0.085 0" quat="1 1 0 0"/>
            <geom class="visual" type="cylinder" size="0.045 0.025" pos="-0.1525 0.085 0" quat="1 1 0 0"/>
            <body name="front_left_leg" pos="0.1525 0.1225 0" quat="0.258819 0 0.9659258 0">
                <joint type="hinge" axis="0 1 0" pos="0 0 0" range="-1.57 1.57" limited="true" name="front_left_hip_joint"/>
                <geom class="visual" type="cylinder" size="0.03 0.0125" pos="0 0 0" quat="1 1 0 0" rgba="0 1 0 1"/>
                <body name="front_left_thigh" pos="0 0 0">
                    <geom class="visual" type="box" size="0.0925 0.02 0.0115" pos="0.0925 0 0" quat="1 1 0 0" rgba="1 0 0 1"/>
                    <geom class="visual" type="cylinder" size="0.02 0.0115" pos="0.185 0 0" quat="1 1 0 0" rgba="1 0 0 1"/>
                    <body name="front_left_knee" pos="0.185 0 0" quat="0.5 0 -0.8660254 0">
                        <joint type="hinge" axis="0 1 0" pos="0 0 0" range="-0.57 1.91" limited="true" name="front_left_knee_joint"/>
                        <geom class="collision" type="sphere" size="0.02" pos="0 0 0" rgba="1 0 0 0.5"/>
                        <body name="front_left_calf" pos="0 0 0">
                            <geom class="visual" type="box" size="0.085 0.0175 0.0115" pos="0.085 0 0" quat="1 1 0 0" rgba="0 0 1 1"/>
                            <geom class="visual" type="cylinder" size="0.0175 0.0115" pos="0.17 0 0" quat="1 1 0 0" rgba="0 0 1 1"/>
                            <body name="front_left_foot" pos="0.17 0 0">
                                <geom class="collision" type="sphere" size="0.025" pos="0 0 0" friction="1 0.005 0.0001"/>
                            </body>
                        </body>
                    </body>
                </body>
            </body>
            <body name="front_right_leg" pos="0.1525 -0.1225 0" quat="0.258819 0 0.9659258 0">
                <joint type="hinge" axis="0 1 0" pos="0 0 0" range="-1.57 1.57" limited="true" name="front_right_hip_joint"/>
                <geom class="visual" type="cylinder" size="0.03 0.0125" pos="0 0 0" quat="1 1 0 0" rgba="0 1 0 1"/>
                <body name="front_right_thigh" pos="0 0 0">
                    <geom class="visual" type="box" size="0.0925 0.02 0.0115" pos="0.0925 0 0" quat="1 1 0 0" rgba="1 0 0 1"/>
                    <geom class="visual" type="cylinder" size="0.02 0.0115" pos="0.185 0 0" quat="1 1 0 0" rgba="1 0 0 1"/>
                    <body name="front_right_knee" pos="0.185 0 0" quat="0.5 0 -0.8660254 0">
                        <joint type="hinge" axis="0 1 0" pos="0 0 0"  range="-0.57 1.91" limited="true" name="front_right_knee_joint"/>
                        <geom class="collision" type="sphere" size="0.02" pos="0 0 0" rgba="1 0 0 0.5"/>
                        <body name="front_right_calf" pos="0 0 0">
                            <geom class="visual" type="box" size="0.085 0.0175 0.0115" pos="0.085 0 0" quat="1 1 0 0" rgba="0 0 1 1"/>
                            <geom class="visual" type="cylinder" size="0.0175 0.0115" pos="0.17 0 0" quat="1 1 0 0" rgba="0 0 1 1"/>
                            <body name="front_right_foot" pos="0.17 0 0">
                                <geom class="collision" type="sphere" size="0.025" pos="0 0 0" friction="1 0.005 0.0001"/>
                            </body>
                        </body>
                    </body>
                </body>
            </body>
            <body name="back_left_leg" pos="-0.1525 0.1225 0" quat="0.258819 0 0.9659258 0">
                <joint type="hinge" axis="0 1 0" pos="0 0 0" range="-1.57 1.57" limited="true" name="back_left_hip_joint"/>
                <geom class="visual" type="cylinder" size="0.03 0.0125" pos="0 0 0" quat="1 1 0 0" rgba="0 1 0 1"/>
                <body name="back_left_thigh" pos="0 0 0">
                    <geom class="visual" type="box" size="0.0925 0.02 0.0115" pos="0.0925 0 0" quat="1 1 0 0" rgba="1 0 0 1"/>
                    <geom class="visual" type="cylinder" size="0.02 0.0115" pos="0.185 0 0" quat="1 1 0 0" rgba="1 0 0 1"/>
                    <body name="back_left_knee" pos="0.185 0 0" quat="0.5 0 -0.8660254 0">
                        <joint type="hinge" axis="0 1 0" pos="0 0 0" range="-0.57 1.91" limited="true" name="back_left_knee_joint"/>
                        <geom class="collision" type="sphere" size="0.02" pos="0 0 0" rgba="1 0 0 0.5"/>
                        <body name="back_left_calf" pos="0 0 0">
                            <geom class="visual" type="box" size="0.085 0.0175 0.0115" pos="0.085 0 0" quat="1 1 0 0" rgba="0 0 1 1"/>
                            <geom class="visual" type="cylinder" size="0.0175 0.0115" pos="0.17 0 0" quat="1 1 0 0" rgba="0 0 1 1"/>
                            <body name="back_left_foot" pos="0.17 0 0">
                                <geom class="collision" type="sphere" size="0.025" pos="0 0 0" friction="1 0.005 0.0001"/>
                            </body>
                        </body>
                    </body>
                </body>
            </body>
            <body name="back_right_leg" pos="-0.1525 -0.1225 0" quat="0.258819 0 0.9659258 0">
                <joint type="hinge" axis="0 1 0" pos="0 0 0" range="-1.57 1.57" limited="true" name="back_right_hip_joint"/>
                <geom class="visual" type="cylinder" size="0.03 0.0125" pos="0 0 0" quat="1 1 0 0" rgba="0 1 0 1"/>
                <body name="back_right_thigh" pos="0 0 0">
                    <geom class="visual" type="box" size="0.0925 0.02 0.0115" pos="0.0925 0 0" quat="1 1 0 0" rgba="1 0 0 1"/>
                    <geom class="visual" type="cylinder" size="0.02 0.0115" pos="0.185 0 0" quat="1 1 0 0" rgba="1 0 0 1"/>
                    <body name="back_right_knee" pos="0.185 0 0" quat="0.5 0 -0.8660254 0">
                        <joint type="hinge" axis="0 1 0" pos="0 0 0" range="-0.57 1.91" limited="true" name="back_right_knee_joint"/>
                        <geom class="collision" type="sphere" size="0.02" pos="0 0 0" rgba="1 0 0 0.5"/>
                        <body name="back_right_calf" pos="0 0 0">
                            <geom class="visual" type="box" size="0.085 0.0175 0.0115" pos="0.085 0 0" quat="1 1 0 0" rgba="0 0 1 1"/>
                            <geom class="visual" type="cylinder" size="0.0175 0.0115" pos="0.17 0 0" quat="1 1 0 0" rgba="0 0 1 1"/>
                            <body name="back_right_foot" pos="0.17 0 0">
                                <geom class="collision" type="sphere" size="0.025" pos="0 0 0" friction="1 0.005 0.0001"/>
                            </body>
                        </body>
                    </body>
                </body>
            </body>
        </body>
    </worldbody>

    <actuator>
        <general class="motors" name="front_left_hip_motor" joint="front_left_hip_joint"/>
        <general class="motors" name="front_right_hip_motor" joint="front_right_hip_joint"/>
        <general class="motors" name="front_left_knee_motor" joint="front_left_knee_joint"/>
        <general class="motors" name="front_right_knee_motor" joint="front_right_knee_joint"/>
        <general class="motors" name="back_left_hip_motor" joint="back_left_hip_joint"/>
        <general class="motors" name="back_right_hip_motor" joint="back_right_hip_joint"/>
        <general class="motors" name="back_left_knee_motor" joint="back_left_knee_joint"/>
        <general class="motors" name="back_right_knee_motor" joint="back_right_knee_joint"/>
    </actuator>

</mujoco>